message - 49 - D:\custom\thirdAssginment\address_book\utility.py
Traceback (most recent call last):
  File "D:\custom\thirdAssginment\address_book\utility.py", line 42, in edit_contact_person
    raise Exception
Exception
Exception occurred from main() and handled at :  - 31 - D:/custom/thirdAssginment/address_book/main.py
